Workbook

Sheet Demand in Thousand kl
A1: Time/Country | B1: 42401 | C1: 42430 | D1: 42461 | E1: 42491 | F1: 42522 | G1: 42552 | H1: 42583 | I1: 42614 | J1: 42644 | K1: 42675 | L1: 42705 | M1: 42736 | N1: 42767 | O1: 42795 | P1: 42826 | Q1: 42856 | R1: 42887 | S1: 42917 | T1: 42948 | U1: 42979 | V1: 43009 | W1: 43040 | X1: 43070 | Y1: 43101 | Z1: 43132 | AA1: 43160 | AB1: 43191 | AC1: 43221 | AD1: 43252 | AE1: 43282 | AF1: 43313 | AG1: 43344 | AH1: 43374 | AI1: 43405 | AJ1: 43435 | AK1: 43466 | AL1: 43497 | AM1: 43525 | AN1: 43556 | AO1: 43586 | AP1: 43617 | AQ1: 43647 | AR1: 43678 | AS1: 43709 | AT1: 43739 | AU1: 43770 | AV1: 43800 | AW1: 43831 | AX1: 43862 | AY1: 43891 | AZ1: 43922 | BA1: 43952 | BB1: 43983 | BC1: 44013 | BD1: 44044 | BE1: 44075 | BF1: 44105 | BG1: 44136 | BH1: 44166 | BI1: 44197 | BJ1: 44228 | BK1: 44256 | BL1: 44287 | BM1: 44317 | BN1: 44348 | BO1: 44378 | BP1: 44409 | BQ1: 44440 | BR1: 44470 | BS1: 44501 | BT1: 44531 | BU1: 44562 | BV1: 44593 | BW1: 44621 | BX1: 44652 | BY1: 44682 | BZ1: 44713 | CA1: 44743 | CB1: 44774 | CC1: 44805 | CD1: 44835 | CE1: 44866 | CF1: 44896 | CG1: 44927 | CH1: 44958 | CI1: 44986 | CJ1: 45017 | CK1: 45047 | CL1: 45078 | CM1: 45108 | CN1: 45139 | CO1: 45170 | CP1: 45200 | CQ1: 45231 | CR1: 45261 | CS1: 45292 | CT1: 45323 | CU1: 45352 | CV1: 45383 | CW1: 45413 | CX1: 45444 | CY1: 45474 | CZ1: 45505 | DA1: 45536 | DB1: 45566 | DC1: 45597 | DD1: 45627 | DE1: 45658 | DF1: 45689 | DG1: 45717 | DH1: 45748 | DI1: 45778 | DJ1: 45809 | DK1: 45839 | DL1: 45870
A2: Albania | B2: - | C2: - | D2: - | E2: - | F2: - | G2: - | H2: - | I2: - | J2: - | K2: - | L2: - | M2: - | N2: - | O2: - | P2: - | Q2: - | R2: - | S2: - | T2: - | U2: - | V2: - | W2: - | X2: - | Y2: - | Z2: - | AA2: - | AB2: - | AC2: - | AD2: - | AE2: - | AF2: - | AG2: - | AH2: - | AI2: - | AJ2: - | AK2: - | AL2: - | AM2: - | AN2: - | AO2: - | AP2: - | AQ2: - | AR2: - | AS2: - | AT2: - | AU2: - | AV2: - | AW2: - | AX2: - | AY2: - | AZ2: - | BA2: - | BB2: - | BC2: - | BD2: - | BE2: - | BF2: - | BG2: - | BH2: - | BI2: - | BJ2: - | BK2: - | BL2: - | BM2: - | BN2: - | BO2: - | BP2: - | BQ2: - | BR2: - | BS2: - | BT2: - | BU2: - | BV2: - | BW2: - | BX2: - | BY2: - | BZ2: - | CA2: - | CB2: - | CC2: - | CD2: - | CE2: - | CF2: - | CG2: - | CH2: - | CI2: - | CJ2: - | CK2: - | CL2: - | CM2: - | CN2: - | CO2: - | CP2: - | CQ2: - | CR2: - | CS2: - | CT2: - | CU2: - | CV2: - | CW2: - | CX2: - | CY2: - | CZ2: - | DA2: - | DB2: - | DC2: - | DD2: - | DE2: - | DF2: - | DG2: - | DH2: - | DI2: - | DJ2: - | DK2: - | DL2: -
A3: Armenia | B3: - | C3: - | D3: - | E3: - | F3: - | G3: - | H3: - | I3: - | J3: - | K3: - | L3: - | M3: - | N3: - | O3: - | P3: - | Q3: - | R3: - | S3: - | T3: - | U3: - | V3: - | W3: - | X3: - | Y3: - | Z3: - | AA3: - | AB3: - | AC3: - | AD3: - | AE3: - | AF3: - | AG3: - | AH3: - | AI3: - | AJ3: - | AK3: - | AL3: - | AM3: - | AN3: - | AO3: - | AP3: - | AQ3: - | AR3: - | AS3: - | AT3: - | AU3: - | AV3: - | AW3: - | AX3: - | AY3: - | AZ3: - | BA3: - | BB3: - | BC3: - | BD3: - | BE3: - | BF3: - | BG3: - | BH3: - | BI3: - | BJ3: - | BK3: - | BL3: - | BM3: - | BN3: - | BO3: - | BP3: - | BQ3: - | BR3: - | BS3: - | BT3: - | BU3: - | BV3: - | BW3: - | BX3: - | BY3: - | BZ3: - | CA3: - | CB3: - | CC3: - | CD3: - | CE3: - | CF3: - | CG3: - | CH3: - | CI3: - | CJ3: - | CK3: - | CL3: - | CM3: - | CN3: - | CO3: - | CP3: - | CQ3: - | CR3: - | CS3: - | CT3: - | CU3: - | CV3: - | CW3: - | CX3: - | CY3: - | CZ3: - | DA3: - | DB3: - | DC3: - | DD3: - | DE3: - | DF3: - | DG3: - | DH3: - | DI3: - | DJ3: - | DK3: - | DL3: -
A4: Austria | B4: 154.4962 | C4: 171.961 | D4: 170.6175 | E4: 200.1733 | F4: 193.4561 | G4: 212.2643 | H4: 229.7291 | I4: 200.1733 | J4: 189.4257 | K4: 159.8699 | L4: 167.9306 | M4: 155.8396 | N4: 137.0314 | O4: 170.6175 | P4: 178.6782 | Q4: 193.4561 | R4: 200.1733 | S4: 213.6077 | T4: 224.3553 | U4: 189.4257 | V4: 184.052 | W4: 161.2134 | X4: 165.2437 | Y4: 157.1831 | Z4: 146.4355 | AA4: 175.9913 | AB4: 180.0216 | AC4: 192.1126 | AD4: 206.8905 | AE4: 217.6381 | AF4: 220.325 | AG4: 193.4561 | AH4: 202.8602 | AI4: 169.2741 | AJ4: 165.2437 | AK4: 155.8396 | AL4: 150.4658 | AM4: 171.961 | AN4: 181.3651 | AO4: 188.0823 | AP4: 205.5471 | AQ4: 218.9815 | AR4: 214.9512 | AS4: 200.1733 | AT4: 192.1126 | AU4: 162.5568 | AV4: 173.3044 | AW4: 165.2437 | AX4: 161.2134 | AY4: 120.91 | AZ4: 73.8895 | BA4: 124.9404 | BB4: 158.5265 | BC4: 206.8905 | BD4: 205.5471 | BE4: 218.9815 | BF4: 159.8699 | BG4: 116.8797 | BH4: 119.5666 | BI4: 96.728 | BJ4: 108.819 | BK4: 126.2838 | BL4: 127.6273 | BM4: 149.1224 | BN4: 190.7692 | BO4: 220.325 | BP4: 221.6684 | BQ4: 209.5774 | BR4: 188.0823 | BS4: 146.4355 | BT4: 150.4658 | BU4: 143.7486 | BV4: 149.1224 | BW4: 170.6175 | BX4: 167.9306 | BY4: 185.3954 | BZ4: 167.9306 | CA4: 171.961 | CB4: 182.7085 | CC4: 201.5167 | CD4: 157.1831 | CE4: 154.4962 | CF4: 162.5568 | CG4: 149.1224 | CH4: 149.1224 | CI4: 174.6478 | CJ4: 173.3044 | CK4: 189.4257 | CL4: 204.2036 | CM4: 210.9209 | CN4: 218.9815 | CO4: 206.8905 | CP4: 184.052 | CQ4: 161.2134 | CR4: 175.9913 | CS4: 161.2134 | CT4: 161.2134 | CU4: 174.6478 | CV4: 178.6782 | CW4: 193.4561 | CX4: 190.7692 | CY4: 217.6381 | CZ4: 225.6988 | DA4: 192.1126 | DB4: 193.4561 | DC4: 165.2437 | DD4: 178.6782 | DE4: 169.2741 | DF4: 161.2134 | DG4: 177.3347 | DH4: 186.7388 | DI4: 188.0823 | DJ4: 205.5471 | DK4: 206.8905 | DL4: 213.6077
A5: Azerbaijan | B5: 120.2741 | C5: 135.1394 | D5: 127.0311 | E5: 132.4366 | F5: 135.1394 | G5: 162.1673 | H5: 170.2757 | I5: 150.0048 | J5: 158.1131 | K5: 150.0048 | L5: 144.5992 | M5: 133.788 | N5: 120.2741 | O5: 143.2478 | P5: 145.9506 | Q5: 143.2478 | R5: 144.5992 | S5: 178.3841 | T5: 163.5187 | U5: 144.5992 | V5: 148.6534 | W5: 136.4908 | X5: 147.302 | Y5: 141.8964 | Z5: 128.3825 | AA5: 150.0048 | AB5: 132.4366 | AC5: 141.8964 | AD5: 155.4103 | AE5: 162.1673 | AF5: 166.2215 | AG5: 151.3562 | AH5: 152.7076 | AI5: 145.9506 | AJ5: 145.9506 | AK5: 141.8964 | AL5: 129.7339 | AM5: 137.8422 | AN5: 139.1936 | AO5: 156.7617 | AP5: 156.7617 | AQ5: 175.6813 | AR5: 181.0868 | AS5: 144.5992 | AT5: 174.3299 | AU5: 143.2478 | AV5: 160.8159 | AW5: 152.7076 | AX5: 140.545 | AY5: 137.8422 | AZ5: 74.3267 | BA5: 129.7339 | BB5: 118.9227 | BC5: 128.3825 | BD5: 140.545 | BE5: 159.4645 | BF5: 131.0852 | BG5: 139.1936 | BH5: 136.4908 | BI5: 143.2478 | BJ5: 141.8964 | BK5: 159.4645 | BL5: 155.4103 | BM5: 112.1657 | BN5: 170.2757 | BO5: 214.8717 | BP5: 178.3841 | BQ5: 160.8159 | BR5: 163.5187 | BS5: 164.8701 | BT5: 148.6534 | BU5: 155.4103 | BV5: 159.4645 | BW5: 170.2757 | BX5: 163.5187 | BY5: 162.1673 | BZ5: 171.6271 | CA5: 206.7633 | CB5: 191.898 | CC5: 178.3841 | CD5: 185.141 | CE5: 174.3299 | CF5: 178.3841 | CG5: 151.3562 | CH5: 156.7617 | CI5: 168.9243 | CJ5: 162.1673 | CK5: 178.3841 | CL5: 202.7091 | CM5: 209.4661 | CN5: 187.8438 | CO5: 162.1673 | CP5: 177.0327 | CQ5: 172.9785 | CR5: 194.6008 | CS5: 177.0327 | CT5: 178.3841 | CU5: 177.0327 | CV5: 183.7896 | CW5: 171.6271 | CX5: 183.7896 | CY5: 202.7091 | CZ5: 198.655 | DA5: 227.0342 | DB5: 187.8438 | DC5: 171.6271 | DD5: 151.3562 | DE5: 177.0327 | DF5: 162.1673 | DG5: 171.6271 | DH5: 186.4924 | DI5: 175.6813 | DJ5: 183.7896 | DK5: 186.4924 | DL5: -
A6: Belarus | B6: 114.8685 | C6: 114.8685 | D6: 137.8422 | E6: 145.9506 | F6: 137.8422 | G6: 152.7076 | H6: 158.1131 | I6: 127.0311 | J6: 148.6534 | K6: 131.0852 | L6: 125.6797 | M6: 121.6255 | N6: 125.6797 | O6: 128.3825 | P6: 143.2478 | Q6: 162.1673 | R6: 125.6797 | S6: 160.8159 | T6: 162.1673 | U6: 122.9769 | V6: 139.1936 | W6: 137.8422 | X6: 136.4908 | Y6: 128.3825 | Z6: 118.9227 | AA6: 125.6797 | AB6: 143.2478 | AC6: 159.4645 | AD6: 148.6534 | AE6: 163.5187 | AF6: 155.4103 | AG6: 151.3562 | AH6: 145.9506 | AI6: 143.2478 | AJ6: 150.0048 | AK6: 122.9769 | AL6: 122.9769 | AM6: 137.8422 | AN6: 147.302 | AO6: 151.3562 | AP6: 151.3562 | AQ6: 164.8701 | AR6: 179.7354 | AS6: 160.8159 | AT6: 159.4645 | AU6: 155.4103 | AV6: 150.0048 | AW6: 140.545 | AX6: 129.7339 | AY6: 128.3825 | AZ6: 144.5992 | BA6: 154.059 | BB6: 133.788 | BC6: 151.3562 | BD6: 175.6813 | BE6: 163.5187 | BF6: 155.4103 | BG6: 151.3562 | BH6: 143.2478 | BI6: 141.8964 | BJ6: 132.4366 | BK6: 135.1394 | BL6: 156.7617 | BM6: - | BN6: - | BO6: - | BP6: - | BQ6: - | BR6: - | BS6: - | BT6: - | BU6: - | BV6: - | BW6: - | BX6: - | BY6: - | BZ6: - | CA6: - | CB6: - | CC6: - | CD6: - | CE6: - | CF6: - | CG6: - | CH6: - | CI6: - | CJ6: - | CK6: - | CL6: - | CM6: - | CN6: - | CO6: - | CP6: - | CQ6: - | CR6: - | CS6: - | CT6: - | CU6: - | CV6: - | CW6: - | CX6: - | CY6: - | CZ6: - | DA6: - | DB6: - | DC6: - | DD6: - | DE6: - | DF6: - | DG6: - | DH6: - | DI6: - | DJ6: - | DK6: - | DL6: -
A7: Belgium | B7: 147.7789 | C7: 167.9306 | D7: 163.9003 | E7: 178.6782 | F7: 169.2741 | G7: 162.5568 | H7: 171.961 | I7: 170.6175 | J7: 169.2741 | K7: 165.2437 | L7: 173.3044 | M7: 151.8093 | N7: 151.8093 | O7: 180.0216 | P7: 170.6175 | Q7: 189.4257 | R7: 180.0216 | S7: 167.9306 | T7: 178.6782 | U7: 175.9913 | V7: 184.052 | W7: 175.9913 | X7: 174.6478 | Y7: 174.6478 | Z7: 165.2437 | AA7: 188.0823 | AB7: 189.4257 | AC7: 210.9209 | AD7: 197.4864 | AE7: 193.4561 | AF7: 198.8299 | AG7: 189.4257 | AH7: 214.9512 | AI7: 200.1733 | AJ7: 200.1733 | AK7: 204.2036 | AL7: 189.4257 | AM7: 205.5471 | AN7: 223.0119 | AO7: 228.3856 | AP7: 213.6077 | AQ7: 223.0119 | AR7: 217.6381 | AS7: 218.9815 | AT7: 235.1029 | AU7: 217.6381 | AV7: 233.7594 | AW7: 223.0119 | AX7: 209.5774 | AY7: 167.9306 | AZ7: 71.2026 | BA7: 131.6576 | BB7: 193.4561 | BC7: 216.2946 | BD7: 193.4561 | BE7: 217.6381 | BF7: 200.1733 | BG7: 162.5568 | BH7: 190.7692 | BI7: 177.3347 | BJ7: 166.5872 | BK7: 201.5167 | BL7: 201.5167 | BM7: 220.325 | BN7: 240.4766 | BO7: 233.7594 | BP7: 243.1635 | BQ7: 255.2545 | BR7: 257.9414 | BS7: 239.1332 | BT7: 247.1939 | BU7: 224.3553 | BV7: 232.416 | BW7: 271.3759 | BX7: 255.2545 | BY7: 274.0628 | BZ7: 253.9111 | CA7: 233.7594 | CB7: 256.598 | CC7: 257.9414 | CD7: 260.6283 | CE7: 248.5373 | CF7: 252.5676 | CG7: 241.8201 | CH7: 237.7898 | CI7: 268.689 | CJ7: 259.2849 | CK7: 282.1234 | CL7: 275.4062 | CM7: 260.6283 | CN7: 283.4669 | CO7: 283.4669 | CP7: 294.2144 | CQ7: 288.8407 | CR7: 287.4972 | CS7: 280.78 | CT7: 283.4669 | CU7: 292.871 | CV7: 307.6489 | CW7: 318.3965 | CX7: 288.8407 | CY7: 304.962 | CZ7: 304.962 | DA7: 295.5579 | DB7: 323.7702 | DC7: 302.2751 | DD7: 313.0227 | DE7: 311.6792 | DF7: 294.2144 | DG7: 311.6792 | DH7: 327.8006 | DI7: 322.4268 | DJ7: 314.3661 | DK7: 314.3661 | DL7: 308.9923
A8: Bulgaria | B8: 40.3033 | C8: 47.0206 | D8: 64.4854 | E8: 59.1116 | F8: 29.5558 | G8: 71.2026 | H8: 59.1116 | I8: 67.1722 | J8: 60.455 | K8: 49.7075 | L8: 67.1722 | M8: 51.0509 | N8: 40.3033 | O8: 55.0812 | P8: 55.0812 | Q8: 63.1419 | R8: 69.8591 | S8: 49.7075 | T8: 68.5157 | U8: 71.2026 | V8: 49.7075 | W8: 67.1722 | X8: 42.9902 | Y8: 44.3337 | Z8: 49.7075 | AA8: 56.4247 | AB8: 21.4951 | AC8: 38.9599 | AD8: 56.4247 | AE8: 107.4756 | AF8: 47.0206 | AG8: 55.0812 | AH8: 84.637 | AI8: 36.273 | AJ8: 26.8689 | AK8: 55.0812 | AL8: 49.7075 | AM8: 52.3944 | AN8: 64.4854 | AO8: 63.1419 | AP8: 60.455 | AQ8: 40.3033 | AR8: 68.5157 | AS8: 61.7985 | AT8: 48.364 | AU8: 53.7378 | AV8: 44.3337 | AW8: 53.7378 | AX8: 37.6165 | AY8: 37.6165 | AZ8: 30.8992 | BA8: 57.7681 | BB8: 55.0812 | BC8: 52.3944 | BD8: 67.1722 | BE8: 63.1419 | BF8: 55.0812 | BG8: 51.0509 | BH8: 41.6468 | BI8: 48.364 | BJ8: 49.7075 | BK8: 47.0206 | BL8: 65.8288 | BM8: 45.6771 | BN8: 60.455 | BO8: 67.1722 | BP8: 68.5157 | BQ8: 61.7985 | BR8: 56.4247 | BS8: 63.1419 | BT8: 34.9296 | BU8: 55.0812 | BV8: 47.0206 | BW8: 71.2026 | BX8: 41.6468 | BY8: 59.1116 | BZ8: 77.9198 | CA8: 48.364 | CB8: 61.7985 | CC8: 69.8591 | CD8: 56.4247 | CE8: 51.0509 | CF8: 59.1116 | CG8: 13.4344 | CH8: 52.3944 | CI8: 45.6771 | CJ8: 40.3033 | CK8: 61.7985 | CL8: 60.455 | CM8: 92.6977 | CN8: 106.1322 | CO8: 69.8591 | CP8: 61.7985 | CQ8: 65.8288 | CR8: 51.0509 | CS8: 69.8591 | CT8: 67.1722 | CU8: 48.364 | CV8: 57.7681 | CW8: 65.8288 | CX8: 77.9198 | CY8: 76.5764 | CZ8: 94.0411 | DA8: 68.5157 | DB8: 75.2329 | DC8: 84.637 | DD8: 55.0812 | DE8: 61.7985 | DF8: 75.2329 | DG8: 56.4247 | DH8: 75.2329 | DI8: 100.7584 | DJ8: 30.8992 | DK8: - | DL8: -
A9: Croatia | B9: 40.3033 | C9: 45.6771 | D9: 53.7378 | E9: 67.1722 | F9: 96.728 | G9: 52.3944 | H9: 85.9805 | I9: 61.7985 | J9: 48.364 | K9: 57.7681 | L9: 67.1722 | M9: 42.9902 | N9: 42.9902 | O9: 38.9599 | P9: 51.0509 | Q9: 65.8288 | R9: 59.1116 | S9: 77.9198 | T9: 81.9501 | U9: 69.8591 | V9: 68.5157 | W9: 51.0509 | X9: 55.0812 | Y9: 52.3944 | Z9: 36.273 | AA9: 44.3337 | AB9: 55.0812 | AC9: 57.7681 | AD9: 61.7985 | AE9: 77.9198 | AF9: 81.9501 | AG9: 59.1116 | AH9: 52.3944 | AI9: 42.9902 | AJ9: 47.0206 | AK9: 49.7075 | AL9: 37.6165 | AM9: 52.3944 | AN9: 75.2329 | AO9: 52.3944 | AP9: 42.9902 | AQ9: 71.2026 | AR9: 81.9501 | AS9: 57.7681 | AT9: 52.3944 | AU9: 41.6468 | AV9: 57.7681 | AW9: 32.2427 | AX9: 44.3337 | AY9: 40.3033 | AZ9: 24.182 | BA9: 45.6771 | BB9: 49.7075 | BC9: 67.1722 | BD9: 65.8288 | BE9: 48.364 | BF9: 42.9902 | BG9: 41.6468 | BH9: 34.9296 | BI9: 32.2427 | BJ9: 37.6165 | BK9: 41.6468 | BL9: 41.6468 | BM9: 51.0509 | BN9: 47.0206 | BO9: 84.637 | BP9: 84.637 | BQ9: 55.0812 | BR9: 45.6771 | BS9: 36.273 | BT9: 45.6771 | BU9: 36.273 | BV9: 36.273 | BW9: 42.9902 | BX9: 48.364 | BY9: 52.3944 | BZ9: 61.7985 | CA9: 76.5764 | CB9: 84.637 | CC9: 57.7681 | CD9: 68.5157 | CE9: 42.9902 | CF9: 30.8992 | CG9: 40.3033 | CH9: 38.9599 | CI9: 47.0206 | CJ9: 59.1116 | CK9: 55.0812 | CL9: 68.5157 | CM9: 72.546 | CN9: 92.6977 | CO9: 71.2026 | CP9: 42.9902 | CQ9: 47.0206 | CR9: 49.7075 | CS9: 45.6771 | CT9: 44.3337 | CU9: 45.6771 | CV9: 63.1419 | CW9: 64.4854 | CX9: 77.9198 | CY9: 92.6977 | CZ9: 85.9805 | DA9: 67.1722 | DB9: 63.1419 | DC9: 51.0509 | DD9: 56.4247 | DE9: 65.8288 | DF9: 32.2427 | DG9: 40.3033 | DH9: 57.7681 | DI9: 81.9501 | DJ9: 76.5764 | DK9: 79.2633 | DL9: -
A10: Cyprus | B10: 36.4876 | C10: 40.5418 | D10: 39.1904 | E10: 37.839 | F10: 41.8932 | G10: 43.2446 | H10: 43.2446 | I10: 43.2446 | J10: 39.1904 | K10: 37.839 | L10: 40.5418 | M10: 35.1363 | N10: 35.1363 | O10: 40.5418 | P10: 36.4876 | Q10: 40.5418 | R10: 43.2446 | S10: 43.2446 | T10: 41.8932 | U10: 41.8932 | V10: 40.5418 | W10: 37.839 | X10: 39.1904 | Y10: 35.1363 | Z10: 33.7849 | AA10: 39.1904 | AB10: 37.839 | AC10: 40.5418 | AD10: 40.5418 | AE10: 41.8932 | AF10: 41.8932 | AG10: 39.1904 | AH10: 39.1904 | AI10: 36.4876 | AJ10: 36.4876 | AK10: 35.1363 | AL10: 32.4335 | AM10: 36.4876 | AN10: 36.4876 | AO10: 39.1904 | AP10: 37.839 | AQ10: 41.8932 | AR10: 40.5418 | AS10: 39.1904 | AT10: 37.839 | AU10: 35.1363 | AV10: 36.4876 | AW10: 33.7849 | AX10: 33.7849 | AY10: 25.6765 | AZ10: 10.8112 | BA10: 25.6765 | BB10: 35.1363 | BC10: 41.8932 | BD10: 37.839 | BE10: 40.5418 | BF10: 36.4876 | BG10: 29.7307 | BH10: 33.7849 | BI10: 22.9737 | BJ10: 25.6765 | BK10: 32.4335 | BL10: 32.4335 | BM10: 32.4335 | BN10: 39.1904 | BO10: 40.5418 | BP10: 37.839 | BQ10: 40.5418 | BR10: 36.4876 | BS10: 33.7849 | BT10: 36.4876 | BU10: 28.3793 | BV10: 29.7307 | BW10: 33.7849 | BX10: 32.4335 | BY10: 36.4876 | BZ10: 36.4876 | CA10: 36.4876 | CB10: 37.839 | CC10: 39.1904 | CD10: 36.4876 | CE10: 33.7849 | CF10: 36.4876 | CG10: 32.4335 | CH10: 31.0821 | CI10: 36.4876 | CJ10: 33.7849 | CK10: 37.839 | CL10: 40.5418 | CM10: 39.1904 | CN10: 39.1904 | CO10: 39.1904 | CP10: 37.839 | CQ10: 36.4876 | CR10: 36.4876 | CS10: 33.7849 | CT10: 33.7849 | CU10: 36.4876 | CV10: 36.4876 | CW10: 37.839 | CX10: 39.1904 | CY10: 41.8932 | CZ10: 39.1904 | DA10: 40.5418 | DB10: 40.5418 | DC10: 36.4876 | DD10: 37.839 | DE10: 35.1363 | DF10: 32.4335 | DG10: 36.4876 | DH10: 36.4876 | DI10: 40.5418 | DJ10: 40.5418 | DK10: 43.2446 | DL10: -
A11: Czech Republic | B11: 159.8699 | C11: 161.2134 | D11: 177.3347 | E11: 197.4864 | F11: 188.0823 | G11: 196.143 | H11: 192.1126 | I11: 193.4561 | J11: 189.4257 | K11: 175.9913 | L11: 174.6478 | M11: 150.4658 | N11: 149.1224 | O11: 173.3044 | P11: 175.9913 | Q11: 194.7995 | R11: 189.4257 | S11: 193.4561 | T11: 208.234 | U11: 181.3651 | V11: 190.7692 | W11: 185.3954 | X11: 161.2134 | Y11: 143.7486 | Z11: 151.8093 | AA11: 158.5265 | AB11: 177.3347 | AC11: 204.2036 | AD11: 184.052 | AE11: 192.1126 | AF11: 192.1126 | AG11: 182.7085 | AH11: 196.143 | AI11: 182.7085 | AJ11: 163.9003 | AK11: 159.8699 | AL11: 147.7789 | AM11: 173.3044 | AN11: 184.052 | AO11: 198.8299 | AP11: 197.4864 | AQ11: 194.7995 | AR11: 198.8299 | AS11: 184.052 | AT11: 200.1733 | AU11: 171.961 | AV11: 167.9306 | AW11: 153.1527 | AX11: 155.8396 | AY11: 139.7183 | AZ11: 123.5969 | BA11: 161.2134 | BB11: 180.0216 | BC11: 197.4864 | BD11: 204.2036 | BE11: 186.7388 | BF11: 155.8396 | BG11: 134.3445 | BH11: 139.7183 | BI11: 128.9707 | BJ11: 124.9404 | BK11: 114.1928 | BL11: 134.3445 | BM11: 184.052 | BN11: 198.8299 | BO11: 217.6381 | BP11: 208.234 | BQ11: 193.4561 | BR11: 200.1733 | BS11: 177.3347 | BT11: 157.1831 | BU11: 157.1831 | BV11: 155.8396 | BW11: 171.961 | BX11: 171.961 | BY11: 182.7085 | BZ11: 196.143 | CA11: 171.961 | CB11: 190.7692 | CC11: 204.2036 | CD11: 188.0823 | CE11: 181.3651 | CF11: 170.6175 | CG11: 159.8699 | CH11: 154.4962 | CI11: 185.3954 | CJ11: 173.3044 | CK11: 213.6077 | CL11: 205.5471 | CM11: 205.5471 | CN11: 204.2036 | CO11: 201.5167 | CP11: 197.4864 | CQ11: 178.6782 | CR11: 174.6478 | CS11: 181.3651 | CT11: 167.9306 | CU11: 186.7388 | CV11: 204.2036 | CW11: 216.2946 | CX11: 200.1733 | CY11: 216.2946 | CZ11: 218.9815 | DA11: 208.234 | DB11: 217.6381 | DC11: 193.4561 | DD11: 208.234 | DE11: 177.3347 | DF11: 173.3044 | DG11: 200.1733 | DH11: 201.5167 | DI11: 218.9815 | DJ11: 220.325 | DK11: 224.3553 | DL11: 223.0119
A12: Denmark | B12: 133.001 | C12: 145.0921 | D12: 146.4355 | E12: 167.9306 | F12: 159.8699 | G12: 147.7789 | H12: 161.2134 | I12: 154.4962 | J12: 145.0921 | K12: 151.8093 | L12: 141.0617 | M12: 135.6879 | N12: 124.9404 | O12: 150.4658 | P12: 139.7183 | Q12: 170.6175 | R12: 161.2134 | S12: 154.4962 | T12: 149.1224 | U12: 147.7789 | V12: 154.4962 | W12: 147.7789 | X12: 141.0617 | Y12: 139.7183 | Z12: 128.9707 | AA12: 137.0314 | AB12: 145.0921 | AC12: 171.961 | AD12: 154.4962 | AE12: 151.8093 | AF12: 161.2134 | AG12: 143.7486 | AH12: 157.1831 | AI12: 150.4658 | AJ12: 142.4052 | AK12: 135.6879 | AL12: 120.91 | AM12: 145.0921 | AN12: 157.1831 | AO12: 165.2437 | AP12: 151.8093 | AQ12: 153.1527 | AR12: 157.1831 | AS12: 149.1224 | AT12: 151.8093 | AU12: 149.1224 | AV12: 146.4355 | AW12: 137.0314 | AX12: 126.2838 | AY12: 120.91 | AZ12: 110.1625 | BA12: 135.6879 | BB12: 150.4658 | BC12: 159.8699 | BD12: 153.1527 | BE12: 159.8699 | BF12: 149.1224 | BG12: 133.001 | BH12: 128.9707 | BI12: 106.1322 | BJ12: 106.1322 | BK12: 137.0314 | BL12: 139.7183 | BM12: 150.4658 | BN12: 162.5568 | BO12: 161.2134 | BP12: 158.5265 | BQ12: 157.1831 | BR12: 147.7789 | BS12: 150.4658 | BT12: 142.4052 | BU12: 124.9404 | BV12: 130.3142 | BW12: 146.4355 | BX12: 143.7486 | BY12: 153.1527 | BZ12: 146.4355 | CA12: 137.0314 | CB12: 154.4962 | CC12: 142.4052 | CD12: 143.7486 | CE12: 147.7789 | CF12: 143.7486 | CG12: 135.6879 | CH12: 133.001 | CI12: 149.1224 | CJ12: 146.4355 | CK12: 163.9003 | CL12: 158.5265 | CM12: 143.7486 | CN12: 161.2134 | CO12: 149.1224 | CP12: 149.1224 | CQ12: 147.7789 | CR12: 142.4052 | CS12: 128.9707 | CT12: 126.2838 | CU12: 134.3445 | CV12: 146.4355 | CW12: 159.8699 | CX12: 135.6879 | CY12: 142.4052 | CZ12: 142.4052 | DA12: 139.7183 | DB12: 135.6879 | DC12: 128.9707 | DD12: 128.9707 | DE12: 123.5969 | DF12: 116.8797 | DG12: 126.2838 | DH12: 138.3748 | DI12: 141.0617 | DJ12: 134.3445 | DK12: 134.3445 | DL12: 135.6879
A13: Estonia | B13: 26.8689 | C13: 24.182 | D13: 24.182 | E13: 29.5558 | F13: 28.2123 | G13: 33.5861 | H13: 30.8992 | I13: 28.2123 | J13: 24.182 | K13: 25.5255 | L13: 25.5255 | M13: 41.6468 | N13: 30.8992 | O13: 30.8992 | P13: 22.8386 | Q13: 29.5558 | R13: 30.8992 | S13: 29.5558 | T13: 30.8992 | U13: 25.5255 | V13: 25.5255 | W13: 24.182 | X13: 26.8689 | Y13: 24.182 | Z13: 28.2123 | AA13: 28.2123 | AB13: 25.5255 | AC13: 32.2427 | AD13: 33.5861 | AE13: 32.2427 | AF13: 33.5861 | AG13: 24.182 | AH13: 24.182 | AI13: 22.8386 | AJ13: 32.2427 | AK13: 34.9296 | AL13: 34.9296 | AM13: 33.5861 | AN13: 30.8992 | AO13: 25.5255 | AP13: 26.8689 | AQ13: 36.273 | AR13: 26.8689 | AS13: 26.8689 | AT13: 28.2123 | AU13: 25.5255 | AV13: 33.5861 | AW13: 34.9296 | AX13: 34.9296 | AY13: 32.2427 | AZ13: 29.5558 | BA13: 29.5558 | BB13: 26.8689 | BC13: 30.8992 | BD13: 29.5558 | BE13: 25.5255 | BF13: 22.8386 | BG13: 22.8386 | BH13: 21.4951 | BI13: 18.8082 | BJ13: 18.8082 | BK13: 18.8082 | BL13: 20.1517 | BM13: 25.5255 | BN13: 28.2123 | BO13: 29.5558 | BP13: 26.8689 | BQ13: 24.182 | BR13: 22.8386 | BS13: 21.4951 | BT13: 22.8386 | BU13: 18.8082 | BV13: 18.8082 | BW13: 20.1517 | BX13: 21.4951 | BY13: 24.182 | BZ13: 25.5255 | CA13: 26.8689 | CB13: 26.8689 | CC13: 22.8386 | CD13: 21.4951 | CE13: 21.4951 | CF13: 21.4951 | CG13: 18.8082 | CH13: 18.8082 | CI13: 20.1517 | CJ13: 21.4951 | CK13: 25.5255 | CL13: 25.5255 | CM13: 26.8689 | CN13: 26.8689 | CO13: 24.182 | CP13: 22.8386 | CQ13: 21.4951 | CR13: 21.4951 | CS13: 20.1517 | CT13: 18.8082 | CU13: 21.4951 | CV13: 21.4951 | CW13: 25.5255 | CX13: 26.8689 | CY13: 26.8689 | CZ13: 26.8689 | DA13: 22.8386 | DB13: 22.8386 | DC13: 21.4951 | DD13: 21.4951 | DE13: 20.1517 | DF13: 20.1517 | DG13: 21.4951 | DH13: 22.8386 | DI13: 32.2427 | DJ13: 26.8689 | DK13: 48.364 | DL13: 26.8689
A14: Finland | B14: 141.0617 | C14: 153.1527 | D14: 157.1831 | E14: 177.3347 | F14: 181.3651 | G14: 194.7995 | H14: 182.7085 | I14: 166.5872 | J14: 162.5568 | K14: 151.8093 | L14: 153.1527 | M14: 139.7183 | N14: 137.0314 | O14: 154.4962 | P14: 151.8093 | Q14: 171.961 | R14: 184.052 | S14: 189.4257 | T14: 181.3651 | U14: 163.9003 | V14: 161.2134 | W14: 146.4355 | X14: 151.8093 | Y14: 142.4052 | Z14: 138.3748 | AA14: 154.4962 | AB14: 149.1224 | AC14: 175.9913 | AD14: 175.9913 | AE14: 190.7692 | AF14: 178.6782 | AG14: 157.1831 | AH14: 158.5265 | AI14: 146.4355 | AJ14: 149.1224 | AK14: 145.0921 | AL14: 130.3142 | AM14: 146.4355 | AN14: 150.4658 | AO14: 165.2437 | AP14: 178.6782 | AQ14: 185.3954 | AR14: 175.9913 | AS14: 157.1831 | AT14: 158.5265 | AU14: 143.7486 | AV14: 145.0921 | AW14: 135.6879 | AX14: 135.6879 | AY14: 127.6273 | AZ14: 111.5059 | BA14: 143.7486 | BB14: 171.961 | BC14: 200.1733 | BD14: 161.2134 | BE14: 157.1831 | BF14: 151.8093 | BG14: 135.6879 | BH14: 135.6879 | BI14: 124.9404 | BJ14: 124.9404 | BK14: 130.3142 | BL14: 137.0314 | BM14: 158.5265 | BN14: 177.3347 | BO14: 192.1126 | BP14: 169.2741 | BQ14: 153.1527 | BR14: 150.4658 | BS14: 138.3748 | BT14: 146.4355 | BU14: 120.91 | BV14: 119.5666 | BW14: 130.3142 | BX14: 131.6576 | BY14: 147.7789 | BZ14: 161.2134 | CA14: 166.5872 | CB14: 159.8699 | CC14: 143.7486 | CD14: 139.7183 | CE14: 133.001 | CF14: 138.3748 | CG14: 123.5969 | CH14: 123.5969 | CI14: 134.3445 | CJ14: 135.6879 | CK14: 154.4962 | CL14: 163.9003 | CM14: 167.9306 | CN14: 157.1831 | CO14: 145.0921 | CP14: 145.0921 | CQ14: 130.3142 | CR14: 139.7183 | CS14: 134.3445 | CT14: 128.9707 | CU14: 139.7183 | CV14: 126.2838 | CW14: 155.8396 | CX14: 159.8699 | CY14: 170.6175 | CZ14: 161.2134 | DA14: 147.7789 | DB14: 141.0617 | DC14: 131.6576 | DD14: 137.0314 | DE14: 126.2838 | DF14: 120.91 | DG14: 134.3445 | DH14: 138.3748 | DI14: 151.8093 | DJ14: 165.2437 | DK14: 177.3347 | DL14: -
A15: France | B15: 690.5307 | C15: 793.976 | D15: 795.3194 | E15: 896.0778 | F15: 826.2186 | G15: 909.5122 | H15: 925.6336 | I15: 840.9965 | J15: 798.0063 | K15: 756.3595 | L15: 840.9965 | M15: 749.6423 | N15: 718.743 | O15: 867.8654 | P15: 865.1785 | Q15: 916.2295 | R15: 951.159 | S15: 922.9467 | T15: 998.1796 | U15: 944.4418 | V15: 834.2793 | W15: 827.5621 | X15: 879.9564 | Y15: 775.1677 | Z15: 759.0464 | AA15: 883.9868 | AB15: 906.8253 | AC15: 983.4017 | AD15: 953.8459 | AE15: 1030.422 | AF15: 1035.796 | AG15: 879.9564 | AH15: 965.9369 | AI15: 897.4212 | AJ15: 853.0875 | AK15: 845.0269 | AL15: 811.4407 | AM15: 897.4212 | AN15: 992.8058 | AO15: 980.7148 | AP15: 996.8361 | AQ15: 1139.241 | AR15: 1076.099 | AS15: 972.6541 | AT15: 1004.897 | AU15: 905.4819 | AV15: 1016.988 | AW15: 931.0073 | AX15: 877.2695 | AY15: 714.7127 | AZ15: 296.9013 | BA15: 587.0854 | BB15: 944.4418 | BC15: 1167.454 | BD15: 1086.847 | BE15: 1010.271 | BF15: 988.7755 | BG15: 596.4896 | BH15: 904.1384 | BI15: 784.5718 | BJ15: 772.4808 | BK15: 951.159 | BL15: 828.9055 | BM15: 943.0983 | BN15: 1131.181 | BO15: 1235.969 | BP15: 1203.727 | BQ15: 1125.807 | BR15: 1073.413 | BS15: 1029.079 | BT15: 1105.655 | BU15: 922.9467 | BV15: 955.1894 | BW15: 1078.786 | BX15: 1093.564 | BY15: 1171.484 | BZ15: 1190.292 | CA15: 1244.03 | CB15: 1285.677 | CC15: 1226.565 | CD15: 1084.16 | CE15: 1109.686 | CF15: 1166.11 | CG15: 1089.534 | CH15: 976.6845 | CI15: 1155.363 | CJ15: 1116.403 | CK15: 1238.656 | CL15: 1308.515 | CM15: 1296.424 | CN15: 1339.415 | CO15: 1209.1 | CP15: 1230.596 | CQ15: 1101.625 | CR15: 1184.918 | CS15: 1139.241 | CT15: 1088.19 | CU15: 1195.666 | CV15: 1270.899 | CW15: 1316.576 | CX15: 1250.747 | CY15: 1487.194 | CZ15: 1426.739 | DA15: 1265.525 | DB15: 1339.415 | DC15: 1187.605 | DD15: 1317.92 | DE15: 1234.626 | DF15: 1152.676 | DG15: 1237.313 | DH15: 1393.152 | DI15: 1348.819 | DJ15: 1429.425 | DK15: 1539.588 | DL15: 1434.799
A16: Georgia | B16: - | C16: - | D16: - | E16: - | F16: - | G16: - | H16: - | I16: - | J16: - | K16: - | L16: - | M16: 8.1084 | N16: 47.2988 | O16: 55.4072 | P16: 59.4614 | Q16: 58.11 | R16: 56.7586 | S16: 72.9753 | T16: 67.5697 | U16: 79.7323 | V16: 68.9211 | W16: 63.5155 | X16: 72.9753 | Y16: 52.7044 | Z16: 50.0016 | AA16: 58.11 | AB16: 55.4072 | AC16: 59.4614 | AD16: 67.5697 | AE16: 66.2183 | AF16: 81.0837 | AG16: 54.0558 | AH16: 64.8669 | AI16: 59.4614 | AJ16: 55.4072 | AK16: 58.11 | AL16: 66.2183 | AM16: 51.353 | AN16: 64.8669 | AO16: 54.0558 | AP16: 55.4072 | AQ16: 62.1641 | AR16: 74.3267 | AS16: 66.2183 | AT16: 66.2183 | AU16: 59.4614 | AV16: 52.7044 | AW16: 66.2183 | AX16: 54.0558 | AY16: 50.0016 | AZ16: 28.3793 | BA16: 50.0016 | BB16: 56.7586 | BC16: 67.5697 | BD16: 60.8127 | BE16: 63.5155 | BF16: 67.5697 | BG16: 59.4614 | BH16: 62.1641 | BI16: 52.7044 | BJ16: 55.4072 | BK16: 68.9211 | BL16: 63.5155 | BM16: 62.1641 | BN16: 68.9211 | BO16: 67.5697 | BP16: 82.4351 | BQ16: 83.7864 | BR16: 59.4614 | BS16: 68.9211 | BT16: 70.2725 | BU16: 67.5697 | BV16: 67.5697 | BW16: 59.4614 | BX16: 60.8127 | BY16: 77.0295 | BZ16: 64.8669 | CA16: 63.5155 | CB16: 74.3267 | CC16: 94.5976 | CD16: 58.11 | CE16: 68.9211 | CF16: 68.9211 | CG16: 54.0558 | CH16: 59.4614 | CI16: 63.5155 | CJ16: 63.5155 | CK16: 72.9753 | CL16: 81.0837 | CM16: 89.192 | CN16: 74.3267 | CO16: 67.5697 | CP16: 70.2725 | CQ16: 66.2183 | CR16: 72.9753 | CS16: 70.2725 | CT16: 72.9753 | CU16: 71.6239 | CV16: 70.2725 | CW16: 54.0558 | CX16: 79.7323 | CY16: 85.1378 | CZ16: 83.7864 | DA16: 67.5697 | DB16: 81.0837 | DC16: 82.4351 | DD16: 60.8127 | DE16: 90.5434 | DF16: 55.4072 | DG16: 95.949 | DH16: 86.4892 | DI16: 72.9753 | DJ16: 79.7323 | DK16: - | DL16: -
A17: Germany | B17: 1875.4491 | C17: 2025.915 | D17: 2052.784 | E17: 2111.895 | F17: 2080.996 | G17: 2158.916 | H17: 2138.764 | I17: 2125.33 | J17: 2064.875 | K17: 2054.127 | L17: 2016.511 | M17: 1903.662 | N17: 1802.903 | O17: 2176.381 | P17: 2025.915 | Q17: 2165.633 | R17: 2132.047 | S17: 2129.36 | T17: 2173.694 | U17: 2091.744 | V17: 2066.218 | W17: 2132.047 | X17: 2001.733 | Y17: 2267.735 | Z17: 2161.603 | AA17: 2392.675 | AB17: 2359.089 | AC17: 2509.555 | AD17: 2497.464 | AE17: 2465.222 | AF17: 2537.768 | AG17: 2318.786 | AH17: 2317.443 | AI17: 2317.443 | AJ17: 2338.938 | AK17: 2262.361 | AL17: 2123.987 | AM17: 2364.463 | AN17: 2338.938 | AO17: 2506.868 | AP17: 2402.08 | AQ17: 2548.515 | AR17: 2547.172 | AS17: 2406.11 | AT17: 2543.141 | AU17: 2314.756 | AV17: 2407.453 | AW17: 2432.979 | AX17: 2265.048 | AY17: 2119.956 | AZ17: 1673.932 | BA17: 2035.319 | BB17: 2224.745 | BC17: 2545.828 | BD17: 2380.584 | BE17: 2344.311 | BF17: 2408.797 | BG17: 1997.703 | BH17: 2117.269 | BI17: 1781.408 | BJ17: 1671.246 | BK17: 2189.815 | BL17: 2039.349 | BM17: 2140.108 | BN17: 2283.856 | BO17: 2334.907 | BP17: 2431.635 | BQ17: 2302.665 | BR17: 2318.786 | BS17: 2262.361 | BT17: 2185.785 | BU17: 2015.167 | BV17: 2028.602 | BW17: 2212.654 | BX17: 2107.865 | BY17: 2086.37 | BZ17: 2575.384 | CA17: 2353.716 | CB17: 2521.646 | CC17: 1957.399 | CD17: 2164.29 | CE17: 2191.159 | CF17: 2105.178 | CG17: 2016.511 | CH17: 2038.006 | CI17: 2247.583 | CJ17: 2060.845 | CK17: 2306.695 | CL17: 2238.179 | CM17: 2250.27 | CN17: 2279.826 | CO17: 2298.634 | CP17: 2369.837 | CQ17: 2161.603 | CR17: 2188.472 | CS17: 2025.915 | CT17: 2064.875 | CU17: 2234.149 | CV17: 2338.938 | CW17: 2442.383 | CX17: 2317.443 | CY17: 2528.363 | CZ17: 2492.09 | DA17: 2334.907 | DB17: 2277.139 | DC17: 2248.927 | DD17: 2208.624 | DE17: 2287.887 | DF17: 2161.603 | DG17: 2316.099 | DH17: 2348.342 | DI17: 2326.847 | DJ17: 2441.04 | DK17: 2278.483 | DL17: 2247.583
A18: Greece | B18: 231.0725 | C18: 259.2849 | D18: 279.4365 | E18: 259.2849 | F18: 276.7497 | G18: 311.6792 | H18: 329.144 | I18: 282.1234 | J18: 251.2242 | K18: 251.2242 | L18: 296.9013 | M18: 206.8905 | N18: 223.0119 | O18: 255.2545 | P18: 248.5373 | Q18: 266.0021 | R18: 279.4365 | S18: 307.6489 | T18: 315.7096 | U18: 278.0931 | V18: 252.5676 | W18: 240.4766 | X18: 284.8103 | Y18: 231.0725 | Z18: 217.6381 | AA18: 249.8808 | AB18: 249.8808 | AC18: 251.2242 | AD18: 270.0324 | AE18: 295.5579 | AF18: 307.6489 | AG18: 259.2849 | AH18: 247.1939 | AI18: 236.4463 | AJ18: 270.0324 | AK18: 213.6077 | AL18: 206.8905 | AM18: 241.8201 | AN18: 251.2242 | AO18: 256.598 | AP18: 267.3455 | AQ18: 306.3054 | AR18: 310.3358 | AS18: 261.9718 | AT18: 251.2242 | AU18: 235.1029 | AV18: 261.9718 | AW18: 217.6381 | AX18: 221.6684 | AY18: 170.6175 | AZ18: 107.4756 | BA18: 192.1126 | BB18: 243.1635 | BC18: 287.4972 | BD18: 283.4669 | BE18: 257.9414 | BF18: 237.7898 | BG18: 163.9003 | BH18: 171.961 | BI18: 154.4962 | BJ18: 154.4962 | BK18: 170.6175 | BL18: 186.7388 | BM18: 224.3553 | BN18: 264.6587 | BO18: 302.2751 | BP18: 302.2751 | BQ18: 267.3455 | BR18: 229.7291 | BS18: 224.3553 | BT18: 252.5676 | BU18: 190.7692 | BV18: 202.8602 | BW18: 202.8602 | BX18: 233.7594 | BY18: 229.7291 | BZ18: 239.1332 | CA18: 261.9718 | CB18: 291.5276 | CC18: 253.9111 | CD18: 220.325 | CE18: 210.9209 | CF18: 251.2242 | CG18: 198.8299 | CH18: 200.1733 | CI18: 223.0119 | CJ18: 228.3856 | CK18: 243.1635 | CL18: 260.6283 | CM18: 291.5276 | CN18: 294.2144 | CO18: 251.2242 | CP18: 235.1029 | CQ18: 217.6381 | CR18: 247.1939 | CS18: 206.8905 | CT18: 202.8602 | CU18: 228.3856 | CV18: 232.416 | CW18: 247.1939 | CX18: 263.3152 | CY18: 298.2448 | CZ18: 306.3054 | DA18: 257.9414 | DB18: 243.1635 | DC18: 229.7291 | DD18: 245.8504 | DE18: 212.2643 | DF18: 201.5167 | DG18: 228.3856 | DH18: 243.1635 | DI18: 247.1939 | DJ18: 268.689 | DK18: 306.3054 | DL18: -
A19: Hungary | B19: 111.5059 | C19: 150.4658 | D19: 162.5568 | E19: 154.4962 | F19: 162.5568 | G19: 155.8396 | H19: 175.9913 | I19: 159.8699 | J19: 124.9404 | K19: 139.7183 | L19: 182.7085 | M19: 119.5666 | N19: 134.3445 | O19: 141.0617 | P19: 123.5969 | Q19: 163.9003 | R19: 163.9003 | S19: 162.5568 | T19: 180.0216 | U19: 151.8093 | V19: 163.9003 | W19: 141.0617 | X19: 154.4962 | Y19: 145.0921 | Z19: 128.9707 | AA19: 162.5568 | AB19: 155.8396 | AC19: 177.3347 | AD19: 170.6175 | AE19: 171.961 | AF19: 175.9913 | AG19: 163.9003 | AH19: 146.4355 | AI19: 149.1224 | AJ19: 185.3954 | AK19: 150.4658 | AL19: 135.6879 | AM19: 158.5265 | AN19: 174.6478 | AO19: 161.2134 | AP19: 175.9913 | AQ19: 182.7085 | AR19: 194.7995 | AS19: 171.961 | AT19: 177.3347 | AU19: 158.5265 | AV19: 169.2741 | AW19: 146.4355 | AX19: 150.4658 | AY19: 139.7183 | AZ19: 116.8797 | BA19: 153.1527 | BB19: 163.9003 | BC19: 175.9913 | BD19: 185.3954 | BE19: 165.2437 | BF19: 157.1831 | BG19: 149.1224 | BH19: 147.7789 | BI19: 134.3445 | BJ19: 134.3445 | BK19: 130.3142 | BL19: 155.8396 | BM19: 175.9913 | BN19: 182.7085 | BO19: 186.7388 | BP19: 192.1126 | BQ19: 178.6782 | BR19: 175.9913 | BS19: 166.5872 | BT19: 171.961 | BU19: 143.7486 | BV19: 158.5265 | BW19: 182.7085 | BX19: 174.6478 | BY19: 190.7692 | BZ19: 182.7085 | CA19: 163.9003 | CB19: 185.3954 | CC19: 171.961 | CD19: 180.0216 | CE19: 141.0617 | CF19: 181.3651 | CG19: 153.1527 | CH19: 131.6576 | CI19: 163.9003 | CJ19: 158.5265 | CK19: 174.6478 | CL19: 169.2741 | CM19: 186.7388 | CN19: 170.6175 | CO19: 167.9306 | CP19: 169.2741 | CQ19: 167.9306 | CR19: 186.7388 | CS19: 134.3445 | CT19: 147.7789 | CU19: 167.9306 | CV19: 170.6175 | CW19: 174.6478 | CX19: 163.9003 | CY19: 189.4257 | CZ19: 184.052 | DA19: 167.9306 | DB19: 180.0216 | DC19: 178.6782 | DD19: 173.3044 | DE19: 151.8093 | DF19: 146.4355 | DG19: 162.5568 | DH19: 175.9913 | DI19: 182.7085 | DJ19: 174.6478 | DK19: 186.7388 | DL19: 185.3954
A20: Iceland | B20: 10.7476 | C20: 13.4344 | D20: 13.4344 | E20: 16.1213 | F20: 18.8082 | G20: 17.4648 | H20: 18.8082 | I20: 14.7779 | J20: 13.4344 | K20: 16.1213 | L20: 14.7779 | M20: 13.4344 | N20: 9.4041 | O20: 17.4648 | P20: 10.7476 | Q20: 20.1517 | R20: 13.4344 | S20: 18.8082 | T20: 13.4344 | U20: 21.4951 | V20: 18.8082 | W20: 13.4344 | X20: 13.4344 | Y20: 12.091 | Z20: 12.091 | AA20: 13.4344 | AB20: 14.7779 | AC20: 17.4648 | AD20: 16.1213 | AE20: 18.8082 | AF20: 14.7779 | AG20: 17.4648 | AH20: 17.4648 | AI20: 14.7779 | AJ20: 12.091 | AK20: 10.7476 | AL20: 9.4041 | AM20: 10.7476 | AN20: 14.7779 | AO20: 21.4951 | AP20: 14.7779 | AQ20: 14.7779 | AR20: 14.7779 | AS20: 17.4648 | AT20: 12.091 | AU20: 12.091 | AV20: 12.091 | AW20: 17.4648 | AX20: 5.3738 | AY20: 16.1213 | AZ20: 1.3434 | BA20: 10.7476 | BB20: 10.7476 | BC20: 10.7476 | BD20: 17.4648 | BE20: 18.8082 | BF20: 12.091 | BG20: 12.091 | BH20: 4.0303 | BI20: 9.4041 | BJ20: 9.4041 | BK20: 9.4041 | BL20: 10.7476 | BM20: 6.7172 | BN20: 13.4344 | BO20: 13.4344 | BP20: 20.1517 | BQ20: 13.4344 | BR20: 13.4344 | BS20: 12.091 | BT20: 5.3738 | BU20: 10.7476 | BV20: 12.091 | BW20: 12.091 | BX20: 5.3738 | BY20: 16.1213 | BZ20: 6.7172 | CA20: 18.8082 | CB20: 13.4344 | CC20: 17.4648 | CD20: 16.1213 | CE20: 10.7476 | CF20: 8.0607 | CG20: 10.7476 | CH20: 13.4344 | CI20: 12.091 | CJ20: 8.0607 | CK20: 9.4041 | CL20: 9.4041 | CM20: 24.182 | CN20: 14.7779 | CO20: 12.091 | CP20: 14.7779 | CQ20: 13.4344 | CR20: 10.7476 | CS20: 10.7476 | CT20: 9.4041 | CU20: 9.4041 | CV20: 10.7476 | CW20: 12.091 | CX20: 16.1213 | CY20: 14.7779 | CZ20: 17.4648 | DA20: 17.4648 | DB20: 12.091 | DC20: 9.4041 | DD20: 12.091 | DE20: 13.4344 | DF20: 10.7476 | DG20: 8.0607 | DH20: 8.0607 | DI20: 16.1213 | DJ20: 12.091 | DK20: 13.4344 | DL20: 17.4648
A21: Ireland | B21: 108.819 | C21: 116.8797 | D21: 116.8797 | E21: 115.5363 | F21: 112.8494 | G21: 110.1625 | H21: 111.5059 | I21: 112.8494 | J21: 106.1322 | K21: 107.4756 | L21: 110.1625 | M21: 95.3846 | N21: 92.6977 | O21: 116.8797 | P21: 102.1018 | Q21: 108.819 | R21: 103.4453 | S21: 103.4453 | T21: 103.4453 | U21: 96.728 | V21: 102.1018 | W21: 94.0411 | X21: 96.728 | Y21: 88.6674 | Z21: 85.9805 | AA21: 88.6674 | AB21: 87.3239 | AC21: 102.1018 | AD21: 95.3846 | AE21: 91.3543 | AF21: 95.3846 | AG21: 87.3239 | AH21: 90.0108 | AI21: 90.0108 | AJ21: 88.6674 | AK21: 83.2936 | AL21: 79.2633 | AM21: 88.6674 | AN21: 88.6674 | AO21: 92.6977 | AP21: 87.3239 | AQ21: 91.3543 | AR21: 91.3543 | AS21: 85.9805 | AT21: 87.3239 | AU21: 84.637 | AV21: 87.3239 | AW21: 77.9198 | AX21: 76.5764 | AY21: 68.5157 | AZ21: 25.5255 | BA21: 47.0206 | BB21: 57.7681 | BC21: 77.9198 | BD21: 76.5764 | BE21: 77.9198 | BF21: 60.455 | BG21: 49.7075 | BH21: 73.8895 | BI21: 37.6165 | BJ21: 40.3033 | BK21: 56.4247 | BL21: 65.8288 | BM21: 69.8591 | BN21: 79.2633 | BO21: 83.2936 | BP21: 77.9198 | BQ21: 81.9501 | BR21: 79.2633 | BS21: 71.2026 | BT21: 73.8895 | BU21: 65.8288 | BV21: 65.8288 | BW21: 79.2633 | BX21: 77.9198 | BY21: 79.2633 | BZ21: 77.9198 | CA21: 79.2633 | CB21: 80.6067 | CC21: 80.6067 | CD21: 79.2633 | CE21: 79.2633 | CF21: 79.2633 | CG21: 72.546 | CH21: 75.2329 | CI21: 83.2936 | CJ21: 81.9501 | CK21: 98.0715 | CL21: 81.9501 | CM21: 85.9805 | CN21: 98.0715 | CO21: 79.2633 | CP21: 84.637 | CQ21: 84.637 | CR21: 83.2936 | CS21: 81.9501 | CT21: 77.9198 | CU21: 92.6977 | CV21: 83.2936 | CW21: 96.728 | CX21: 87.3239 | CY21: 96.728 | CZ21: 90.0108 | DA21: 91.3543 | DB21: 92.6977 | DC21: 87.3239 | DD21: 91.3543 | DE21: 81.9501 | DF21: 81.9501 | DG21: 92.6977 | DH21: 94.0411 | DI21: 102.1018 | DJ21: 92.6977 | DK21: 98.0715 | DL21: 98.0715
A22: Italy | B22: 955.1894 | C22: 1038.483 | D22: 1008.927 | E22: 1070.726 | F22: 995.4927 | G22: 1094.908 | H22: 1081.473 | I22: 1039.826 | J22: 945.7852 | K22: 874.5827 | L22: 968.6238 | M22: 854.431 | N22: 840.9965 | O22: 988.7755 | P22: 990.1189 | Q22: 963.25 | R22: 1054.604 | S22: 1057.291 | T22: 1059.978 | U22: 926.977 | V22: 947.1287 | W22: 900.1081 | X22: 961.9066 | Y22: 901.4516 | Z22: 890.704 | AA22: 992.8058 | AB22: 973.9976 | AC22: 998.1796 | AD22: 1049.231 | AE22: 1082.817 | AF22: 1068.039 | AG22: 941.7549 | AH22: 994.1493 | AI22: 910.8557 | AJ22: 969.9672 | AK22: 724.1168 | AL22: 662.3184 | AM22: 768.4505 | AN22: 853.0875 | AO22: 807.4104 | AP22: 862.4917 | AQ22: 924.2901 | AR22: 881.2999 | AS22: 976.6845 | AT22: 1018.331 | AU22: 867.8654 | AV22: 898.7647 | AW22: 871.8958 | AX22: 818.158 | AY22: 541.4083 | AZ22: 382.8818 | BA22: 662.3184 | BB22: 854.431 | BC22: 1004.897 | BD22: 960.5631 | BE22: 952.5025 | BF22: 904.1384 | BG22: 702.6217 | BH22: 811.4407 | BI22: 654.2577 | BJ22: 771.1374 | BK22: 807.4104 | BL22: 822.1883 | BM22: 963.25 | BN22: 1047.887 | BO22: 1143.272 | BP22: 1076.099 | BQ22: 1002.21 | BR22: 1008.927 | BS22: 961.9066 | BT22: 980.7148 | BU22: 831.5924 | BV22: 877.2695 | BW22: 964.5935 | BX22: 967.2804 | BY22: 1016.988 | BZ22: 1025.049 | CA22: 1115.059 | CB22: 1106.999 | CC22: 1069.382 | CD22: 980.7148 | CE22: 994.1493 | CF22: 996.8361 | CG22: 857.1179 | CH22: 834.2793 | CI22: 983.4017 | CJ22: 947.1287 | CK22: 1058.635 | CL22: 1100.281 | CM22: 1117.746 | CN22: 1148.645 | CO22: 1049.231 | CP22: 1046.544 | CQ22: 980.7148 | CR22: 1029.079 | CS22: 964.5935 | CT22: 910.8557 | CU22: 1021.018 | CV22: 979.3714 | CW22: 1027.735 | CX22: 1026.392 | CY22: 1227.909 | CZ22: 1195.666 | DA22: 1077.443 | DB22: 1106.999 | DC22: 967.2804 | DD22: 978.0279 | DE22: 955.1894 | DF22: 908.1688 | DG22: 1002.21 | DH22: 1058.635 | DI22: 1077.443 | DJ22: 1117.746 | DK22: 1166.11 | DL22: 1070.726
A23: Kazakhstan | B23: - | C23: - | D23: - | E23: - | F23: - | G23: - | H23: - | I23: - | J23: - | K23: - | L23: - | M23: - | N23: - | O23: - | P23: - | Q23: - | R23: - | S23: - | T23: - | U23: - | V23: - | W23: - | X23: - | Y23: - | Z23: - | AA23: - | AB23: - | AC23: - | AD23: - | AE23: - | AF23: - | AG23: - | AH23: - | AI23: - | AJ23: - | AK23: - | AL23: - | AM23: - | AN23: - | AO23: - | AP23: - | AQ23: - | AR23: - | AS23: - | AT23: - | AU23: - | AV23: - | AW23: - | AX23: - | AY23: - | AZ23: - | BA23: - | BB23: - | BC23: - | BD23: - | BE23: - | BF23: - | BG23: - | BH23: - | BI23: - | BJ23: - | BK23: - | BL23: - | BM23: - | BN23: - | BO23: - | BP23: - | BQ23: - | BR23: - | BS23: - | BT23: - | BU23: - | BV23: - | BW23: - | BX23: - | BY23: - | BZ23: - | CA23: - | CB23: - | CC23: - | CD23: - | CE23: - | CF23: - | CG23: - | CH23: - | CI23: - | CJ23: - | CK23: - | CL23: - | CM23: - | CN23: - | CO23: - | CP23: - | CQ23: - | CR23: - | CS23: - | CT23: - | CU23: - | CV23: - | CW23: - | CX23: - | CY23: - | CZ23: - | DA23: - | DB23: - | DC23: - | DD23: - | DE23: - | DF23: - | DG23: - | DH23: - | DI23: - | DJ23: - | DK23: - | DL23: -
A24: Latvia | B24: 17.4648 | C24: 20.1517 | D24: 21.4951 | E24: 25.5255 | F24: 25.5255 | G24: 25.5255 | H24: 26.8689 | I24: 22.8386 | J24: 21.4951 | K24: 18.8082 | L24: 20.1517 | M24: 17.4648 | N24: 17.4648 | O24: 18.8082 | P24: 20.1517 | Q24: 24.182 | R24: 22.8386 | S24: 24.182 | T24: 25.5255 | U24: 21.4951 | V24: 21.4951 | W24: 18.8082 | X24: 20.1517 | Y24: 17.4648 | Z24: 16.1213 | AA24: 18.8082 | AB24: 20.1517 | AC24: 22.8386 | AD24: 22.8386 | AE24: 24.182 | AF24: 24.182 | AG24: 21.4951 | AH24: 20.1517 | AI24: 18.8082 | AJ24: 18.8082 | AK24: 16.1213 | AL24: 17.4648 | AM24: 18.8082 | AN24: 17.4648 | AO24: 22.8386 | AP24: 22.8386 | AQ24: 22.8386 | AR24: 22.8386 | AS24: 18.8082 | AT24: 18.8082 | AU24: 16.1213 | AV24: 18.8082 | AW24: 16.1213 | AX24: 14.7779 | AY24: 16.1213 | AZ24: 14.7779 | BA24: 20.1517 | BB24: 21.4951 | BC24: 22.8386 | BD24: 22.8386 | BE24: 18.8082 | BF24: 18.8082 | BG24: 16.1213 | BH24: 16.1213 | BI24: 13.4344 | BJ24: 13.4344 | BK24: 14.7779 | BL24: 17.4648 | BM24: 20.1517 | BN24: 21.4951 | BO24: 21.4951 | BP24: 22.8386 | BQ24: 18.8082 | BR24: 18.8082 | BS24: 14.7779 | BT24: 17.4648 | BU24: 14.7779 | BV24: 13.4344 | BW24: 17.4648 | BX24: 14.7779 | BY24: 18.8082 | BZ24: 20.1517 | CA24: 20.1517 | CB24: 20.1517 | CC24: 17.4648 | CD24: 17.4648 | CE24: 14.7779 | CF24: 16.1213 | CG24: 14.7779 | CH24: 13.4344 | CI24: 16.1213 | CJ24: 16.1213 | CK24: 21.4951 | CL24: 20.1517 | CM24: 20.1517 | CN24: 21.4951 | CO24: 18.8082 | CP24: 17.4648 | CQ24: 16.1213 | CR24: 16.1213 | CS24: 16.1213 | CT24: 14.7779 | CU24: 16.1213 | CV24: 17.4648 | CW24: 20.1517 | CX24: 21.4951 | CY24: 21.4951 | CZ24: 22.8386 | DA24: 20.1517 | DB24: 17.4648 | DC24: 16.1213 | DD24: 17.4648 | DE24: 14.7779 | DF24: 14.7779 | DG24: 17.4648 | DH24: 17.4648 | DI24: 20.1517 | DJ24: 21.4951 | DK24: 22.8386 | DL24: 22.8386
A25: Lithuania | B25: 17.4648 | C25: 21.4951 | D25: 28.2123 | E25: 26.8689 | F25: 26.8689 | G25: 28.2123 | H25: 29.5558 | I25: 26.8689 | J25: 25.5255 | K25: 25.5255 | L25: 24.182 | M25: 21.4951 | N25: 18.8082 | O25: 22.8386 | P25: 21.4951 | Q25: 28.2123 | R25: 24.182 | S25: 28.2123 | T25: 26.8689 | U25: 25.5255 | V25: 24.182 | W25: 22.8386 | X25: 24.182 | Y25: 20.1517 | Z25: 22.8386 | AA25: 24.182 | AB25: 25.5255 | AC25: 28.2123 | AD25: 32.2427 | AE25: 28.2123 | AF25: 32.2427 | AG25: 25.5255 | AH25: 25.5255 | AI25: 24.182 | AJ25: 25.5255 | AK25: 22.8386 | AL25: 20.1517 | AM25: 22.8386 | AN25: 28.2123 | AO25: 26.8689 | AP25: 28.2123 | AQ25: 29.5558 | AR25: 29.5558 | AS25: 29.5558 | AT25: 29.5558 | AU25: 25.5255 | AV25: 28.2123 | AW25: 24.182 | AX25: 24.182 | AY25: 21.4951 | AZ25: 20.1517 | BA25: 37.6165 | BB25: 33.5861 | BC25: 34.9296 | BD25: 34.9296 | BE25: 34.9296 | BF25: 29.5558 | BG25: 24.182 | BH25: 21.4951 | BI25: 18.8082 | BJ25: 20.1517 | BK25: 22.8386 | BL25: 26.8689 | BM25: 22.8386 | BN25: 37.6165 | BO25: 38.9599 | BP25: 36.273 | BQ25: 33.5861 | BR25: 32.2427 | BS25: 26.8689 | BT25: 30.8992 | BU25: 26.8689 | BV25: 25.5255 | BW25: 28.2123 | BX25: 30.8992 | BY25: 34.9296 | BZ25: 34.9296 | CA25: 37.6165 | CB25: 36.273 | CC25: 32.2427 | CD25: 32.2427 | CE25: 29.5558 | CF25: 30.8992 | CG25: 29.5558 | CH25: 26.8689 | CI25: 30.8992 | CJ25: 34.9296 | CK25: 37.6165 | CL25: 38.9599 | CM25: 37.6165 | CN25: 40.3033 | CO25: 36.273 | CP25: 36.273 | CQ25: 30.8992 | CR25: 34.9296 | CS25: 32.2427 | CT25: 28.2123 | CU25: 34.9296 | CV25: 36.273 | CW25: 42.9902 | CX25: 38.9599 | CY25: 45.6771 | CZ25: 48.364 | DA25: 37.6165 | DB25: 38.9599 | DC25: 36.273 | DD25: 34.9296 | DE25: 26.8689 | DF25: 33.5861 | DG25: 34.9296 | DH25: 38.9599 | DI25: 42.9902 | DJ25: 42.9902 | DK25: 45.6771 | DL25: 48.364
A26: Luxembourg | B26: 25.5255 | C26: 30.8992 | D26: 33.5861 | E26: 41.6468 | F26: 32.2427 | G26: 36.273 | H26: 38.9599 | I26: 33.5861 | J26: 33.5861 | K26: 29.5558 | L26: 33.5861 | M26: 30.8992 | N26: 29.5558 | O26: 29.5558 | P26: 34.9296 | Q26: 37.6165 | R26: 36.273 | S26: 38.9599 | T26: 38.9599 | U26: 34.9296 | V26: 36.273 | W26: 32.2427 | X26: 29.5558 | Y26: 30.8992 | Z26: 29.5558 | AA26: 33.5861 | AB26: 36.273 | AC26: 41.6468 | AD26: 38.9599 | AE26: 41.6468 | AF26: 41.6468 | AG26: 37.6165 | AH26: 40.3033 | AI26: 37.6165 | AJ26: 38.9599 | AK26: 34.9296 | AL26: 32.2427 | AM26: 36.273 | AN26: 42.9902 | AO26: 42.9902 | AP26: 42.9902 | AQ26: 47.0206 | AR26: 44.3337 | AS26: 40.3033 | AT26: 41.6468 | AU26: 37.6165 | AV26: 38.9599 | AW26: 40.3033 | AX26: 30.8992 | AY26: 26.8689 | AZ26: 9.4041 | BA26: 20.1517 | BB26: 34.9296 | BC26: 41.6468 | BD26: 37.6165 | BE26: 37.6165 | BF26: 34.9296 | BG26: 26.8689 | BH26: 30.8992 | BI26: 25.5255 | BJ26: 25.5255 | BK26: 30.8992 | BL26: 30.8992 | BM26: 37.6165 | BN26: 40.3033 | BO26: 47.0206 | BP26: 49.7075 | BQ26: 45.6771 | BR26: 42.9902 | BS26: 40.3033 | BT26: 37.6165 | BU26: 36.273 | BV26: 34.9296 | BW26: 41.6468 | BX26: 41.6468 | BY26: 44.3337 | BZ26: 34.9296 | CA26: 38.9599 | CB26: 40.3033 | CC26: 37.6165 | CD26: 37.6165 | CE26: 34.9296 | CF26: 40.3033 | CG26: 34.9296 | CH26: 36.273 | CI26: 41.6468 | CJ26: 40.3033 | CK26: 47.0206 | CL26: 45.6771 | CM26: 48.364 | CN26: 48.364 | CO26: 44.3337 | CP26: 44.3337 | CQ26: 41.6468 | CR26: 41.6468 | CS26: 36.273 | CT26: 41.6468 | CU26: 42.9902 | CV26: 45.6771 | CW26: 48.364 | CX26: 44.3337 | CY26: 52.3944 | CZ26: 51.0509 | DA26: 44.3337 | DB26: 47.0206 | DC26: 42.9902 | DD26: 44.3337 | DE26: 44.3337 | DF26: 36.273 | DG26: 45.6771 | DH26: 48.364 | DI26: 49.7075 | DJ26: 47.0206 | DK26: 52.3944 | DL26: 48.364
A27: North Macedonia | B27: 9.4598 | C27: 9.4598 | D27: 12.1625 | E27: 10.8112 | F27: 13.5139 | G27: 14.8653 | H27: 16.2167 | I27: 12.1625 | J27: 10.8112 | K27: 10.8112 | L27: 12.1625 | M27: 6.757 | N27: 8.1084 | O27: 9.4598 | P27: 12.1625 | Q27: 10.8112 | R27: 12.1625 | S27: 14.8653 | T27: 16.2167 | U27: 12.1625 | V27: 12.1625 | W27: 10.8112 | X27: 12.1625 | Y27: 9.4598 | Z27: 8.1084 | AA27: 9.4598 | AB27: 10.8112 | AC27: 10.8112 | AD27: 12.1625 | AE27: 14.8653 | AF27: 16.2167 | AG27: 12.1625 | AH27: 10.8112 | AI27: 9.4598 | AJ27: 12.1625 | AK27: 10.8112 | AL27: 8.1084 | AM27: 9.4598 | AN27: 12.1625 | AO27: 10.8112 | AP27: 12.1625 | AQ27: 16.2167 | AR27: 21.6223 | AS27: 5.4056 | AT27: 10.8112 | AU27: 9.4598 | AV27: 10.8112 | AW27: 10.8112 | AX27: 8.1084 | AY27: 8.1084 | AZ27: 5.4056 | BA27: 6.757 | BB27: 6.757 | BC27: 9.4598 | BD27: 9.4598 | BE27: 12.1625 | BF27: 8.1084 | BG27: 8.1084 | BH27: 8.1084 | BI27: 6.757 | BJ27: 8.1084 | BK27: 6.757 | BL27: 6.757 | BM27: 9.4598 | BN27: 10.8112 | BO27: 13.5139 | BP27: 16.2167 | BQ27: 8.1084 | BR27: 9.4598 | BS27: 5.4056 | BT27: 10.8112 | BU27: 8.1084 | BV27: 8.1084 | BW27: 8.1084 | BX27: 10.8112 | BY27: 12.1625 | BZ27: 13.5139 | CA27: 13.5139 | CB27: 14.8653 | CC27: 10.8112 | CD27: - | CE27: - | CF27: - | CG27: - | CH27: - | CI27: - | CJ27: - | CK27: - | CL27: - | CM27: - | CN27: - | CO27: - | CP27: - | CQ27: - | CR27: - | CS27: - | CT27: - | CU27: - | CV27: - | CW27: - | CX27: - | CY27: - | CZ27: - | DA27: - | DB27: - | DC27: - | DD27: - | DE27: - | DF27: - | DG27: - | DH27: - | DI27: - | DJ27: - | DK27: - | DL27: -
A28: Malta | B28: 6.7172 | C28: 8.0607 | D28: 8.0607 | E28: 8.0607 | F28: 8.0607 | G28: 9.4041 | H28: 9.4041 | I28: 9.4041 | J28: 9.4041 | K28: 9.4041 | L28: 8.0607 | M28: 8.0607 | N28: 8.0607 | O28: 8.0607 | P28: 8.0607 | Q28: - | R28: 9.4041 | S28: 9.4041 | T28: 9.4041 | U28: 8.0607 | V28: 9.4041 | W28: 8.0607 | X28: 8.0607 | Y28: 8.0607 | Z28: 8.0607 | AA28: 8.0607 | AB28: 8.0607 | AC28: 8.0607 | AD28: 9.4041 | AE28: 9.4041 | AF28: 9.4041 | AG28: 9.4041 | AH28: 12.091 | AI28: 17.4648 | AJ28: 12.091 | AK28: -8.0607 | AL28: 12.091 | AM28: -4.0303 | AN28: 69.8591 | AO28: 18.8082 | AP28: 21.4951 | AQ28: 0 | AR28: 10.7476 | AS28: 9.4041 | AT28: 8.0607 | AU28: 10.7476 | AV28: 13.4344 | AW28: 8.0607 | AX28: 8.0607 | AY28: 6.7172 | AZ28: 5.3738 | BA28: 5.3738 | BB28: 8.0607 | BC28: 10.7476 | BD28: 9.4041 | BE28: 8.0607 | BF28: 8.0607 | BG28: 8.0607 | BH28: 8.0607 | BI28: 6.7172 | BJ28: 6.7172 | BK28: 6.7172 | BL28: 8.0607 | BM28: 8.0607 | BN28: 9.4041 | BO28: 10.7476 | BP28: 10.7476 | BQ28: 9.4041 | BR28: 8.0607 | BS28: 9.4041 | BT28: 8.0607 | BU28: 6.7172 | BV28: 8.0607 | BW28: 9.4041 | BX28: 8.0607 | BY28: 9.4041 | BZ28: 10.7476 | CA28: 10.7476 | CB28: 12.091 | CC28: 9.4041 | CD28: 9.4041 | CE28: 9.4041 | CF28: 9.4041 | CG28: 8.0607 | CH28: 8.0607 | CI28: 9.4041 | CJ28: 9.4041 | CK28: 9.4041 | CL28: 10.7476 | CM28: 12.091 | CN28: 12.091 | CO28: 9.4041 | CP28: 10.7476 | CQ28: 9.4041 | CR28: 9.4041 | CS28: 8.0607 | CT28: 8.0607 | CU28: 9.4041 | CV28: 9.4041 | CW28: 10.7476 | CX28: 9.4041 | CY28: 12.091 | CZ28: 12.091 | DA28: 9.4041 | DB28: 10.7476 | DC28: 9.4041 | DD28: 9.4041 | DE28: 9.4041 | DF28: 8.0607 | DG28: 9.4041 | DH28: 10.7476 | DI28: 10.7476 | DJ28: 10.7476 | DK28: 12.091 | DL28: -
A29: Moldova | B29: 14.8653 | C29: 17.5681 | D29: 18.9195 | E29: 18.9195 | F29: 18.9195 | G29: 20.2709 | H29: 20.2709 | I29: 20.2709 | J29: 20.2709 | K29: 20.2709 | L29: 20.2709 | M29: 17.5681 | N29: 14.8653 | O29: 16.2167 | P29: 18.9195 | Q29: 18.9195 | R29: 20.2709 | S29: 17.5681 | T29: 22.9737 | U29: 24.3251 | V29: 21.6223 | W29: 20.2709 | X29: 20.2709 | Y29: 17.5681 | Z29: 14.8653 | AA29: 16.2167 | AB29: 20.2709 | AC29: 20.2709 | AD29: 17.5681 | AE29: 18.9195 | AF29: 22.9737 | AG29: 18.9195 | AH29: 20.2709 | AI29: 21.6223 | AJ29: 20.2709 | AK29: 18.9195 | AL29: 16.2167 | AM29: 21.6223 | AN29: 20.2709 | AO29: 21.6223 | AP29: 18.9195 | AQ29: 20.2709 | AR29: 21.6223 | AS29: 20.2709 | AT29: 20.2709 | AU29: 18.9195 | AV29: 27.0279 | AW29: 17.5681 | AX29: 16.2167 | AY29: 14.8653 | AZ29: 13.5139 | BA29: 17.5681 | BB29: 22.9737 | BC29: 18.9195 | BD29: 20.2709 | BE29: 20.2709 | BF29: 20.2709 | BG29: 20.2709 | BH29: 25.6765 | BI29: 17.5681 | BJ29: 16.2167 | BK29: 17.5681 | BL29: 18.9195 | BM29: 20.2709 | BN29: 21.6223 | BO29: 21.6223 | BP29: 22.9737 | BQ29: 21.6223 | BR29: 21.6223 | BS29: 25.6765 | BT29: 21.6223 | BU29: 17.5681 | BV29: 17.5681 | BW29: 20.2709 | BX29: 25.6765 | BY29: 21.6223 | BZ29: 18.9195 | CA29: 25.6765 | CB29: 24.3251 | CC29: 27.0279 | CD29: 27.0279 | CE29: 28.3793 | CF29: 25.6765 | CG29: 25.6765 | CH29: 20.2709 | CI29: 18.9195 | CJ29: 20.2709 | CK29: 33.7849 | CL29: 18.9195 | CM29: 22.9737 | CN29: 18.9195 | CO29: 12.1625 | CP29: 20.2709 | CQ29: 21.6223 | CR29: 18.9195 | CS29: 24.3251 | CT29: 18.9195 | CU29: 18.9195 | CV29: 17.5681 | CW29: 21.6223 | CX29: 22.9737 | CY29: 24.3251 | CZ29: 20.2709 | DA29: 31.0821 | DB29: 18.9195 | DC29: 17.5681 | DD29: 22.9737 | DE29: 21.6223 | DF29: 17.5681 | DG29: 22.9737 | DH29: 18.9195 | DI29: 22.9737 | DJ29: 21.6223 | DK29: 25.6765 | DL29: -
A30: Netherlands | B30: 419.1548 | C30: 454.0844 | D30: 458.1147 | E30: 446.0237 | F30: 460.8016 | G30: 439.3065 | H30: 463.4885 | I30: 452.7409 | J30: 452.7409 | K30: 478.2664 | L30: 458.1147 | M30: 447.3672 | N30: 417.8114 | O30: 484.9836 | P30: 440.6499 | Q30: 476.923 | R30: 471.5492 | S30: 441.9934 | T30: 459.4582 | U30: 443.3368 | V30: 474.2361 | W30: 480.9533 | X30: 464.832 | Y30: 462.1451 | Z30: 436.6196 | AA30: 490.3574 | AB30: 464.832 | AC30: 491.7008 | AD30: 467.5188 | AE30: 470.2057 | AF30: 451.3975 | AG30: 447.3672 | AH30: 498.4181 | AI30: 505.1353 | AJ30: 505.1353 | AK30: 490.3574 | AL30: 450.0541 | AM30: 489.014 | AN30: 491.7008 | AO30: 507.8222 | AP30: 466.1754 | AQ30: 490.3574 | AR30: 455.4278 | AS30: 464.832 | AT30: 511.8525 | AU30: 497.0746 | AV30: 502.4484 | AW30: 486.3271 | AX30: 454.0844 | AY30: 386.9121 | AZ30: 288.8407 | BA30: 389.599 | BB30: 413.781 | BC30: 452.7409 | BD30: 427.2155 | BE30: 448.7106 | BF30: 417.8114 | BG30: 399.0031 | BH30: 411.0942 | BI30: 342.5785 | BJ30: 333.1743 | BK30: 417.8114 | BL30: 429.9024 | BM30: 441.9934 | BN30: 463.4885 | BO30: 476.923 | BP30: 436.6196 | BQ30: 456.7713 | BR30: 460.8016 | BS30: 437.9631 | BT30: 432.5893 | BU30: 378.8515 | BV30: 390.9425 | BW30: 413.781 | BX30: 452.7409 | BY30: 462.1451 | BZ30: 435.2762 | CA30: 423.1852 | CB30: 419.1548 | CC30: 456.7713 | CD30: 459.4582 | CE30: 484.9836 | CF30: 499.7615 | CG30: 471.5492 | CH30: 455.4278 | CI30: 523.9435 | CJ30: 507.8222 | CK30: 476.923 | CL30: 521.2566 | CM30: 412.4376 | CN30: 437.9631 | CO30: 450.0541 | CP30: 455.4278 | CQ30: 467.5188 | CR30: 482.2967 | CS30: 476.923 | CT30: 454.0844 | CU30: 475.5795 | CV30: 470.2057 | CW30: 474.2361 | CX30: 451.3975 | CY30: 482.2967 | CZ30: 437.9631 | DA30: 451.3975 | DB30: 498.4181 | DC30: 464.832 | DD30: 475.5795 | DE30: 464.832 | DF30: 439.3065 | DG30: 474.2361 | DH30: 476.923 | DI30: 497.0746 | DJ30: 479.6098 | DK30: 487.6705 | DL30: 444.6803
A31: Norway | B31: 85.9805 | C31: 90.0108 | D31: 88.6674 | E31: 104.7887 | F31: 108.819 | G31: 114.1928 | H31: 110.1625 | I31: 95.3846 | J31: 95.3846 | K31: 81.9501 | L31: 84.637 | M31: 83.2936 | N31: 77.9198 | O31: 84.637 | P31: 90.0108 | Q31: 103.4453 | R31: 103.4453 | S31: 115.5363 | T31: 103.4453 | U31: 90.0108 | V31: 88.6674 | W31: 88.6674 | X31: 85.9805 | Y31: 81.9501 | Z31: 84.637 | AA31: 87.3239 | AB31: 85.9805 | AC31: 100.7584 | AD31: 103.4453 | AE31: 114.1928 | AF31: 99.4149 | AG31: 87.3239 | AH31: 85.9805 | AI31: 77.9198 | AJ31: 83.2936 | AK31: 75.2329 | AL31: 71.2026 | AM31: 76.5764 | AN31: 87.3239 | AO31: 91.3543 | AP31: 96.728 | AQ31: 108.819 | AR31: 96.728 | AS31: 84.637 | AT31: 79.2633 | AU31: 75.2329 | AV31: 76.5764 | AW31: 72.546 | AX31: 72.546 | AY31: 65.8288 | AZ31: 64.4854 | BA31: 80.6067 | BB31: 99.4149 | BC31: 108.819 | BD31: 99.4149 | BE31: 81.9501 | BF31: 79.2633 | BG31: 67.1722 | BH31: 69.8591 | BI31: 67.1722 | BJ31: 65.8288 | BK31: 72.546 | BL31: 69.8591 | BM31: 84.637 | BN31: 94.0411 | BO31: 112.8494 | BP31: 95.3846 | BQ31: 80.6067 | BR31: 76.5764 | BS31: 72.546 | BT31: 72.546 | BU31: 63.1419 | BV31: 63.1419 | BW31: 75.2329 | BX31: 75.2329 | BY31: 79.2633 | BZ31: 90.0108 | CA31: 96.728 | CB31: 87.3239 | CC31: 76.5764 | CD31: 71.2026 | CE31: 68.5157 | CF31: 71.2026 | CG31: 63.1419 | CH31: 64.4854 | CI31: 72.546 | CJ31: 73.8895 | CK31: 81.9501 | CL31: 88.6674 | CM31: 94.0411 | CN31: 83.2936 | CO31: 72.546 | CP31: 73.8895 | CQ31: 64.4854 | CR31: 71.2026 | CS31: 63.1419 | CT31: 64.4854 | CU31: 68.5157 | CV31: 67.1722 | CW31: 79.2633 | CX31: 80.6067 | CY31: 91.3543 | CZ31: 81.9501 | DA31: 72.546 | DB31: 65.8288 | DC31: 59.1116 | DD31: 65.8288 | DE31: 59.1116 | DF31: 59.1116 | DG31: 64.4854 | DH31: 68.5157 | DI31: 73.8895 | DJ31: 77.9198 | DK31: 94.0411 | DL31: 94.0411
A32: Poland | B32: 386.9121 | C32: 428.5589 | D32: 468.8623 | E32: 435.2762 | F32: 478.2664 | G32: 468.8623 | H32: 513.196 | I32: 480.9533 | J32: 475.5795 | K32: 448.7106 | L32: 467.5188 | M32: 439.3065 | N32: 419.1548 | O32: 439.3065 | P32: 474.2361 | Q32: 521.2566 | R32: 513.196 | S32: 522.6001 | T32: 536.0345 | U32: 483.6402 | V32: 518.5697 | W32: 419.1548 | X32: 484.9836 | Y32: 451.3975 | Z32: 417.8114 | AA32: 497.0746 | AB32: 514.5394 | AC32: 545.4386 | AD32: 523.9435 | AE32: 538.7214 | AF32: 565.5903 | AG32: 523.9435 | AH32: 548.1255 | AI32: 494.3877 | AJ32: 540.0649 | AK32: 456.7713 | AL32: 436.6196 | AM32: 495.7312 | AN32: 541.4083 | AO32: 550.8124 | AP32: 556.1862 | AQ32: 577.6813 | AR32: 573.651 | AS32: 533.3476 | AT32: 566.9338 | AU32: 503.7919 | AV32: 515.8829 | AW32: 494.3877 | AX32: 467.5188 | AY32: 423.1852 | AZ32: 333.1743 | BA32: 428.5589 | BB32: 545.4386 | BC32: 588.4289 | BD32: 611.2674 | BE32: 527.9739 | BF32: 534.6911 | BG32: 443.3368 | BH32: 478.2664 | BI32: 444.6803 | BJ32: 388.2556 | BK32: 464.832 | BL32: 468.8623 | BM32: 560.2165 | BN32: 613.9543 | BO32: 642.1667 | BP32: 638.1363 | BQ32: 570.9641 | BR32: 556.1862 | BS32: 521.2566 | BT32: 564.2469 | BU32: 484.9836 | BV32: 534.6911 | BW32: 595.1461 | BX32: 564.2469 | BY32: 654.2577 | BZ32: 608.5806 | CA32: 604.5502 | CB32: 632.7626 | CC32: 533.3476 | CD32: 573.651 | CE32: 577.6813 | CF32: 592.4592 | CG32: 495.7312 | CH32: 494.3877 | CI32: 580.3682 | CJ32: 603.2068 | CK32: 673.0659 | CL32: 608.5806 | CM32: 669.0356 | CN32: 678.4397 | CO32: 644.8536 | CP32: 707.9955 | CQ32: 573.651 | CR32: 581.7117 | CS32: 599.1764 | CT32: 556.1862 | CU32: 592.4592 | CV32: 648.8839 | CW32: 685.1569 | CX32: 690.5307 | CY32: 729.4906 | CZ32: 685.1569 | DA32: 658.288 | DB32: 656.9446 | DC32: 603.2068 | DD32: 635.4495 | DE32: 612.6109 | DF32: 546.7821 | DG32: 615.2978 | DH32: 702.6217 | DI32: 755.0161 | DJ32: 724.1168 | DK32: 752.3292 | DL32: 745.6119
A33: Portugal | B33: 104.7887 | C33: 122.2535 | D33: 116.8797 | E33: 116.8797 | F33: 118.2232 | G33: 130.3142 | H33: 142.4052 | I33: 120.91 | J33: 114.1928 | K33: 111.5059 | L33: 106.1322 | M33: 104.7887 | N33: 102.1018 | O33: 114.1928 | P33: 110.1625 | Q33: 119.5666 | R33: 119.5666 | S33: 127.6273 | T33: 137.0314 | U33: 118.2232 | V33: 114.1928 | W33: 104.7887 | X33: 116.8797 | Y33: 103.4453 | Z33: 90.0108 | AA33: 111.5059 | AB33: 108.819 | AC33: 119.5666 | AD33: 114.1928 | AE33: 126.2838 | AF33: 135.6879 | AG33: 114.1928 | AH33: 115.5363 | AI33: 104.7887 | AJ33: 118.2232 | AK33: 104.7887 | AL33: 95.3846 | AM33: 114.1928 | AN33: 114.1928 | AO33: 116.8797 | AP33: 116.8797 | AQ33: 134.3445 | AR33: 141.0617 | AS33: 114.1928 | AT33: 115.5363 | AU33: 110.1625 | AV33: 122.2535 | AW33: 111.5059 | AX33: 106.1322 | AY33: 87.3239 | AZ33: 48.364 | BA33: 83.2936 | BB33: 98.0715 | BC33: 118.2232 | BD33: 128.9707 | BE33: 110.1625 | BF33: 106.1322 | BG33: 92.6977 | BH33: 98.0715 | BI33: 75.2329 | BJ33: 64.4854 | BK33: 83.2936 | BL33: 96.728 | BM33: 112.8494 | BN33: 116.8797 | BO33: 123.5969 | BP33: 135.6879 | BQ33: 116.8797 | BR33: 119.5666 | BS33: 128.9707 | BT33: 118.2232 | BU33: 106.1322 | BV33: 95.3846 | BW33: 119.5666 | BX33: 104.7887 | BY33: 123.5969 | BZ33: 124.9404 | CA33: 138.3748 | CB33: 161.2134 | CC33: 128.9707 | CD33: 124.9404 | CE33: 130.3142 | CF33: 124.9404 | CG33: 118.2232 | CH33: 108.819 | CI33: 130.3142 | CJ33: 124.9404 | CK33: 143.7486 | CL33: 130.3142 | CM33: 158.5265 | CN33: 155.8396 | CO33: 130.3142 | CP33: 134.3445 | CQ33: 126.2838 | CR33: 134.3445 | CS33: 120.91 | CT33: 120.91 | CU33: 106.1322 | CV33: 134.3445 | CW33: 145.0921 | CX33: 143.7486 | CY33: 158.5265 | CZ33: 174.6478 | DA33: 143.7486 | DB33: 146.4355 | DC33: 137.0314 | DD33: 147.7789 | DE33: 120.91 | DF33: 124.9404 | DG33: 141.0617 | DH33: 145.0921 | DI33: 138.3748 | DJ33: 159.8699 | DK33: 173.3044 | DL33: 180.0216
A34: Romania | B34: 128.9707 | C34: 139.7183 | D34: 153.1527 | E34: 151.8093 | F34: 151.8093 | G34: 175.9913 | H34: 200.1733 | I34: 163.9003 | J34: 158.5265 | K34: 151.8093 | L34: 134.3445 | M34: 142.4052 | N34: 122.2535 | O34: 145.0921 | P34: 159.8699 | Q34: 175.9913 | R34: 161.2134 | S34: 166.5872 | T34: 209.5774 | U34: 123.5969 | V34: 202.8602 | W34: 122.2535 | X34: 192.1126 | Y34: 137.0314 | Z34: 119.5666 | AA34: 141.0617 | AB34: 150.4658 | AC34: 157.1831 | AD34: 131.6576 | AE34: 169.2741 | AF34: 210.9209 | AG34: 166.5872 | AH34: 173.3044 | AI34: 137.0314 | AJ34: 118.2232 | AK34: 145.0921 | AL34: 149.1224 | AM34: 135.6879 | AN34: 159.8699 | AO34: 134.3445 | AP34: 145.0921 | AQ34: 241.8201 | AR34: 185.3954 | AS34: 166.5872 | AT34: 155.8396 | AU34: 108.819 | AV34: 173.3044 | AW34: 123.5969 | AX34: 174.6478 | AY34: 147.7789 | AZ34: 45.6771 | BA34: 124.9404 | BB34: 166.5872 | BC34: 110.1625 | BD34: 189.4257 | BE34: 158.5265 | BF34: 174.6478 | BG34: 153.1527 | BH34: 80.6067 | BI34: 209.5774 | BJ34: 34.9296 | BK34: 170.6175 | BL34: 64.4854 | BM34: 291.5276 | BN34: 137.0314 | BO34: 189.4257 | BP34: 197.4864 | BQ34: 155.8396 | BR34: 124.9404 | BS34: 198.8299 | BT34: 143.7486 | BU34: 135.6879 | BV34: 142.4052 | BW34: 154.4962 | BX34: 87.3239 | BY34: 231.0725 | BZ34: 123.5969 | CA34: 189.4257 | CB34: 185.3954 | CC34: 159.8699 | CD34: 134.3445 | CE34: 131.6576 | CF34: 182.7085 | CG34: 155.8396 | CH34: 151.8093 | CI34: 175.9913 | CJ34: 173.3044 | CK34: 155.8396 | CL34: 142.4052 | CM34: 170.6175 | CN34: 206.8905 | CO34: 167.9306 | CP34: 165.2437 | CQ34: 150.4658 | CR34: 173.3044 | CS34: 115.5363 | CT34: 175.9913 | CU34: 196.143 | CV34: 193.4561 | CW34: 126.2838 | CX34: 204.2036 | CY34: 181.3651 | CZ34: 206.8905 | DA34: 165.2437 | DB34: 166.5872 | DC34: 193.4561 | DD34: 165.2437 | DE34: 161.2134 | DF34: 123.5969 | DG34: 166.5872 | DH34: 173.3044 | DI34: 173.3044 | DJ34: 190.7692 | DK34: - | DL34: -
